<?xml version="1.0"?>
<!--
  Gazebo ROS differential drive plugin demo

  # MOVEMENT
  Try sending commands:

    ros2 topic pub /demo/cmd_demo geometry_msgs/Twist '{linear: {x: 1.0}}' -1

    ros2 topic pub /demo/cmd_demo geometry_msgs/Twist '{angular: {z: 0.1}}' -1

  Try listening to odometry:

    ros2 topic echo /demo/odom_demo

  Try listening to TF:

    ros2 run tf2_ros tf2_echo odom_demo chassis

    ros2 run tf2_ros tf2_echo chassis right_wheel

    ros2 run tf2_ros tf2_echo chassis left_wheel
    
    
  # SENSOR  
  Then open RVIZ:

      ros2 run rviz2 rviz2

  On RViz, add the following topics:

      * /ray/pointcloud2
      * /ray/pointcloud
      * /ray/laserscan
      * /gpu_ray/pointcloud2
      * /gpu_ray/pointcloud
      * /gpu_ray/laserscan    
    
-->

<sdf version='1.7'>
  <world name='default'>
    <model name='ground_plane'>
      <static>1</static>
      <link name='link'>
        <collision name='collision'>
          <geometry>
            <plane>
              <normal>0 0 1</normal>
              <size>100 100</size>
            </plane>
          </geometry>
          <surface>
            <contact>
              <collide_bitmask>65535</collide_bitmask>
              <ode/>
            </contact>
            <friction>
              <ode>
                <mu>100</mu>
                <mu2>50</mu2>
              </ode>
              <torsional>
                <ode/>
              </torsional>
            </friction>
            <bounce/>
          </surface>
          <max_contacts>10</max_contacts>
        </collision>
        <visual name='visual'>
          <cast_shadows>0</cast_shadows>
          <geometry>
            <plane>
              <normal>0 0 1</normal>
              <size>100 100</size>
            </plane>
          </geometry>
          <material>
            <script>
              <uri>file://media/materials/scripts/gazebo.material</uri>
              <name>Gazebo/Grey</name>
            </script>
          </material>
        </visual>
        <self_collide>0</self_collide>
        <enable_wind>0</enable_wind>
        <kinematic>0</kinematic>
      </link>
    </model>
    <light name='sun' type='directional'>
      <cast_shadows>1</cast_shadows>
      <pose>0 0 10 0 -0 0</pose>
      <diffuse>0.8 0.8 0.8 1</diffuse>
      <specular>0.2 0.2 0.2 1</specular>
      <attenuation>
        <range>1000</range>
        <constant>0.9</constant>
        <linear>0.01</linear>
        <quadratic>0.001</quadratic>
      </attenuation>
      <direction>-0.5 0.1 -0.9</direction>
      <spot>
        <inner_angle>0</inner_angle>
        <outer_angle>0</outer_angle>
        <falloff>0</falloff>
      </spot>
    </light>
    <model name='vehicle'>
      <pose>0 0 0.325 0 -0 0</pose>
      <link name='chassis'>
        <pose>-0.151427 -0 0.175 0 -0 0</pose>
        <inertial>
          <mass>1.14395</mass>
          <inertia>
            <ixx>0.126164</ixx>
            <ixy>0</ixy>
            <ixz>0</ixz>
            <iyy>0.416519</iyy>
            <iyz>0</iyz>
            <izz>0.481014</izz>
          </inertia>
          <pose>0 0 0 0 -0 0</pose>
        </inertial>
        <visual name='visual'>
          <geometry>
            <box>
              <size>2.01142 1 0.568726</size>
            </box>
          </geometry>
        </visual>
        <collision name='collision'>
          <geometry>
            <box>
              <size>2.01142 1 0.568726</size>
            </box>
          </geometry>
          <max_contacts>10</max_contacts>
          <surface>
            <contact>
              <ode/>
            </contact>
            <bounce/>
            <friction>
              <torsional>
                <ode/>
              </torsional>
              <ode/>
            </friction>
          </surface>
        </collision>
        <self_collide>0</self_collide>
        <enable_wind>0</enable_wind>
        <kinematic>0</kinematic>
      </link>
      <link name='left_wheel'>
        <pose>0.554283 0.625029 -0.025 -1.5707 0 0</pose>
        <inertial>
          <mass>2</mass>
          <inertia>
            <ixx>0.145833</ixx>
            <ixy>0</ixy>
            <ixz>0</ixz>
            <iyy>0.145833</iyy>
            <iyz>0</iyz>
            <izz>0.125</izz>
          </inertia>
          <pose>0 0 0 0 -0 0</pose>
        </inertial>
        <visual name='visual'>
          <geometry>
            <sphere>
              <radius>0.3</radius>
            </sphere>
          </geometry>
        </visual>
        <collision name='collision'>
          <geometry>
            <sphere>
              <radius>0.3</radius>
            </sphere>
          </geometry>
          <surface>
            <friction>
              <ode>
                <mu>1</mu>
                <mu2>1</mu2>
                <slip1>0</slip1>
                <slip2>0</slip2>
              </ode>
              <torsional>
                <ode/>
              </torsional>
            </friction>
            <contact>
              <ode>
                <soft_cfm>0</soft_cfm>
                <soft_erp>0.2</soft_erp>
                <kp>1e+13</kp>
                <kd>1</kd>
                <max_vel>0.01</max_vel>
                <min_depth>0.01</min_depth>
              </ode>
            </contact>
            <bounce/>
          </surface>
          <max_contacts>10</max_contacts>
        </collision>
        <self_collide>0</self_collide>
        <enable_wind>0</enable_wind>
        <kinematic>0</kinematic>
      </link>
      <link name='right_wheel'>
        <pose>0.554282 -0.625029 -0.025 -1.5707 0 0</pose>
        <inertial>
          <mass>2</mass>
          <inertia>
            <ixx>0.145833</ixx>
            <ixy>0</ixy>
            <ixz>0</ixz>
            <iyy>0.145833</iyy>
            <iyz>0</iyz>
            <izz>0.125</izz>
          </inertia>
          <pose>0 0 0 0 -0 0</pose>
        </inertial>
        <visual name='visual'>
          <geometry>
            <sphere>
              <radius>0.3</radius>
            </sphere>
          </geometry>
        </visual>
        <collision name='collision'>
          <geometry>
            <sphere>
              <radius>0.3</radius>
            </sphere>
          </geometry>
          <surface>
            <friction>
              <ode>
                <mu>1</mu>
                <mu2>1</mu2>
                <slip1>0</slip1>
                <slip2>0</slip2>
              </ode>
              <torsional>
                <ode/>
              </torsional>
            </friction>
            <contact>
              <ode>
                <soft_cfm>0</soft_cfm>
                <soft_erp>0.2</soft_erp>
                <kp>1e+13</kp>
                <kd>1</kd>
                <max_vel>0.01</max_vel>
                <min_depth>0.01</min_depth>
              </ode>
            </contact>
            <bounce/>
          </surface>
          <max_contacts>10</max_contacts>
        </collision>
        <self_collide>0</self_collide>
        <enable_wind>0</enable_wind>
        <kinematic>0</kinematic>
      </link>
      <link name='caster'>
        <pose>-0.957138 -0 -0.125 0 -0 0</pose>
        <inertial>
          <mass>1</mass>
          <inertia>
            <ixx>0.1</ixx>
            <ixy>0</ixy>
            <ixz>0</ixz>
            <iyy>0.1</iyy>
            <iyz>0</iyz>
            <izz>0.1</izz>
          </inertia>
          <pose>0 0 0 0 -0 0</pose>
        </inertial>
        <visual name='visual'>
          <geometry>
            <sphere>
              <radius>0.2</radius>
            </sphere>
          </geometry>
        </visual>
        <collision name='collision'>
          <geometry>
            <sphere>
              <radius>0.2</radius>
            </sphere>
          </geometry>
          <max_contacts>10</max_contacts>
          <surface>
            <contact>
              <ode/>
            </contact>
            <bounce/>
            <friction>
              <torsional>
                <ode/>
              </torsional>
              <ode/>
            </friction>
          </surface>
        </collision>
        <self_collide>0</self_collide>
        <enable_wind>0</enable_wind>
        <kinematic>0</kinematic>
      </link>
      <model name='ray_sensor_box'>
        <pose>0.822514 0 0.486819 0 -0 0</pose>
        <link name='ray_link'>
          <visual name='visual_box'>
            <geometry>
              <box>
                <size>0.05 0.05 0.05</size>
              </box>
            </geometry>
          </visual>
          <collision name='collision_box'>
            <geometry>
              <box>
                <size>0.05 0.05 0.05</size>
              </box>
            </geometry>
            <laser_retro>100</laser_retro>
            <max_contacts>10</max_contacts>
            <surface>
              <contact>
                <ode/>
              </contact>
              <bounce/>
              <friction>
                <torsional>
                  <ode/>
                </torsional>
                <ode/>
              </friction>
            </surface>
          </collision>
          <sensor name='sensor_ray' type='ray'>
            <ray>
              <scan>
                <horizontal>
                  <samples>600</samples>
                  <resolution>1</resolution>
                  <min_angle>-0.5236</min_angle>
                  <max_angle>0.5236</max_angle>
                </horizontal>
                <vertical>
                  <samples>100</samples>
                  <resolution>1</resolution>
                  <min_angle>-0.5236</min_angle>
                  <max_angle>0.5236</max_angle>
                </vertical>
              </scan>
              <range>
                <min>0.05</min>
                <max>500</max>
              </range>
            </ray>
            <always_on>1</always_on>
            <update_rate>1</update_rate>
            <plugin name='pc2' filename='libgazebo_ros_ray_sensor.so'>
              <ros>
                <namespace>/ray</namespace>
                <remapping>~/out:=pointcloud2</remapping>
              </ros>
              <output_type>sensor_msgs/PointCloud2</output_type>
            </plugin>
            <plugin name='pc' filename='libgazebo_ros_ray_sensor.so'>
              <ros>
                <namespace>/ray</namespace>
                <remapping>~/out:=pointcloud</remapping>
              </ros>
              <output_type>sensor_msgs/PointCloud</output_type>
            </plugin>
            <plugin name='laserscan' filename='libgazebo_ros_ray_sensor.so'>
              <ros>
                <namespace>/ray</namespace>
                <remapping>~/out:=laserscan</remapping>
              </ros>
              <output_type>sensor_msgs/LaserScan</output_type>
            </plugin>
            <plugin name='range' filename='libgazebo_ros_ray_sensor.so'>
              <ros>
                <namespace>/ray</namespace>
                <remapping>~/out:=range</remapping>
              </ros>
              <output_type>sensor_msgs/Range</output_type>
            </plugin>
          </sensor>
          <sensor name='sensor_gpu_ray' type='gpu_ray'>
            <ray>
              <scan>
                <horizontal>
                  <samples>300</samples>
                  <resolution>1</resolution>
                  <min_angle>-0.5236</min_angle>
                  <max_angle>0.5236</max_angle>
                </horizontal>
                <vertical>
                  <samples>1</samples>
                  <min_angle>0</min_angle>
                  <max_angle>0</max_angle>
                </vertical>
              </scan>
              <range>
                <min>0.05</min>
                <max>50</max>
              </range>
            </ray>
            <always_on>1</always_on>
            <update_rate>1</update_rate>
            <plugin name='pc2_gpu' filename='libgazebo_ros_ray_sensor.so'>
              <ros>
                <namespace>/gpu_ray</namespace>
                <remapping>~/out:=pointcloud2</remapping>
              </ros>
              <output_type>sensor_msgs/PointCloud2</output_type>
            </plugin>
            <plugin name='pc_gpu' filename='libgazebo_ros_ray_sensor.so'>
              <ros>
                <namespace>/gpu_ray</namespace>
                <remapping>~/out:=pointcloud</remapping>
              </ros>
              <output_type>sensor_msgs/PointCloud</output_type>
            </plugin>
            <plugin name='laserscan_gpu' filename='libgazebo_ros_ray_sensor.so'>
              <ros>
                <namespace>/gpu_ray</namespace>
                <remapping>~/out:=laserscan</remapping>
              </ros>
              <output_type>sensor_msgs/LaserScan</output_type>
            </plugin>
            <plugin name='range_gpu' filename='libgazebo_ros_ray_sensor.so'>
              <ros>
                <namespace>/gpu_ray</namespace>
                <remapping>~/out:=range</remapping>
              </ros>
              <output_type>sensor_msgs/Range</output_type>
            </plugin>
          </sensor>
          <self_collide>0</self_collide>
          <inertial>
            <pose>0 0 0 0 -0 0</pose>
            <inertia>
              <ixx>1</ixx>
              <ixy>0</ixy>
              <ixz>0</ixz>
              <iyy>1</iyy>
              <iyz>0</iyz>
              <izz>1</izz>
            </inertia>
            <mass>1</mass>
          </inertial>
          <enable_wind>0</enable_wind>
          <kinematic>0</kinematic>
        </link>
      </model>
      <joint name='left_wheel_joint' type='revolute'>
        <parent>chassis</parent>
        <child>left_wheel</child>
        <axis>
          <xyz>0 0 1</xyz>
          <limit>
            <lower>-1.79769e+308</lower>
            <upper>1.79769e+308</upper>
          </limit>
          <dynamics>
            <spring_reference>0</spring_reference>
            <spring_stiffness>0</spring_stiffness>
          </dynamics>
        </axis>
      </joint>
      <joint name='right_wheel_joint' type='revolute'>
        <parent>chassis</parent>
        <child>right_wheel</child>
        <axis>
          <xyz>0 0 1</xyz>
          <limit>
            <lower>-1.79769e+308</lower>
            <upper>1.79769e+308</upper>
          </limit>
          <dynamics>
            <spring_reference>0</spring_reference>
            <spring_stiffness>0</spring_stiffness>
          </dynamics>
        </axis>
      </joint>
      <joint name='caster_wheel' type='ball'>
        <parent>chassis</parent>
        <child>caster</child>
      </joint>
      <joint name='sensor_link' type='revolute'>
        <parent>chassis</parent>
        <child>ray_link</child>
        <pose>0 0 0 0 -0 0</pose>
        <axis>
          <xyz>0 0 1</xyz>
          <limit>
            <lower>-1e+16</lower>
            <upper>1e+16</upper>
          </limit>
          <dynamics>
            <spring_reference>0</spring_reference>
            <spring_stiffness>0</spring_stiffness>
          </dynamics>
        </axis>
      </joint>
      <plugin name='diff_drive' filename='libgazebo_ros_diff_drive.so'>
        <ros>
          <namespace>/demo</namespace>
          <remapping>cmd_vel:=cmd_demo</remapping>
          <remapping>odom:=odom_demo</remapping>
        </ros>
        <left_joint>left_wheel_joint</left_joint>
        <right_joint>right_wheel_joint</right_joint>
        <wheel_separation>1.25</wheel_separation>
        <wheel_diameter>0.6</wheel_diameter>
        <max_wheel_torque>20</max_wheel_torque>
        <max_wheel_acceleration>1.0</max_wheel_acceleration>
        <publish_odom>1</publish_odom>
        <publish_odom_tf>1</publish_odom_tf>
        <publish_wheel_tf>1</publish_wheel_tf>
        <odometry_frame>odom_demo</odometry_frame>
        <robot_base_frame>chassis</robot_base_frame>
      </plugin>
    </model>
    <gravity>0 0 -9.8</gravity>
    <magnetic_field>6e-06 2.3e-05 -4.2e-05</magnetic_field>
    <atmosphere type='adiabatic'/>
    <physics type='ode'>
      <max_step_size>0.001</max_step_size>
      <real_time_factor>1</real_time_factor>
      <real_time_update_rate>1000</real_time_update_rate>
    </physics>
    <scene>
      <ambient>0.4 0.4 0.4 1</ambient>
      <background>0.7 0.7 0.7 1</background>
      <shadows>1</shadows>
    </scene>
    <audio>
      <device>default</device>
    </audio>
    <wind/>
    <spherical_coordinates>
      <surface_model>EARTH_WGS84</surface_model>
      <latitude_deg>0</latitude_deg>
      <longitude_deg>0</longitude_deg>
      <elevation>0</elevation>
      <heading_deg>0</heading_deg>
    </spherical_coordinates>
    <model name='unit_box'>
      <pose>8.68804 -0.310383 0.5 0 -0 0</pose>
      <link name='link'>
        <inertial>
          <mass>1</mass>
          <inertia>
            <ixx>0.166667</ixx>
            <ixy>0</ixy>
            <ixz>0</ixz>
            <iyy>0.166667</iyy>
            <iyz>0</iyz>
            <izz>0.166667</izz>
          </inertia>
          <pose>0 0 0 0 -0 0</pose>
        </inertial>
        <collision name='collision'>
          <geometry>
            <box>
              <size>1 1 1</size>
            </box>
          </geometry>
          <max_contacts>10</max_contacts>
          <surface>
            <contact>
              <ode/>
            </contact>
            <bounce/>
            <friction>
              <torsional>
                <ode/>
              </torsional>
              <ode/>
            </friction>
          </surface>
        </collision>
        <visual name='visual'>
          <geometry>
            <box>
              <size>1 1 1</size>
            </box>
          </geometry>
          <material>
            <script>
              <name>Gazebo/Grey</name>
              <uri>file://media/materials/scripts/gazebo.material</uri>
            </script>
          </material>
        </visual>
        <self_collide>0</self_collide>
        <enable_wind>0</enable_wind>
        <kinematic>0</kinematic>
      </link>
    </model>
    <state world_name='default'>
      <sim_time>60 955000000</sim_time>
      <real_time>62 244363241</real_time>
      <wall_time>1658063013 197176604</wall_time>
      <iterations>60955</iterations>
      <model name='ground_plane'>
        <pose>0 0 0 0 -0 0</pose>
        <scale>1 1 1</scale>
        <link name='link'>
          <pose>0 0 0 0 -0 0</pose>
          <velocity>0 0 0 0 -0 0</velocity>
          <acceleration>0 0 0 0 -0 0</acceleration>
          <wrench>0 0 0 0 -0 0</wrench>
        </link>
      </model>
      <model name='unit_box'>
        <pose>8.68804 -0.310228 0.490621 -0.002688 -1e-06 -0.000539</pose>
        <scale>1 6.98255 1</scale>
        <link name='link'>
          <pose>8.68804 -0.310228 0.490621 -0.002688 -1e-06 -0.000539</pose>
          <velocity>0 0.0049 -0.295769 -0.087628 0 0</velocity>
          <acceleration>8.3e-05 9.8 -0 0.674092 0.000917 0</acceleration>
          <wrench>8.3e-05 9.8 -0 0 -0 0</wrench>
        </link>
      </model>
      <model name='vehicle'>
        <pose>-0.000877 -0.00015 0.324984 1.6e-05 1.4e-05 0.000267</pose>
        <scale>1 1 1</scale>
        <link name='caster'>
          <pose>-0.958017 -0.000404 0.199997 0.015614 0.079067 0.000619</pose>
          <velocity>-0.000289 3.8e-05 -0.002601 0.000256 0.001297 0</velocity>
          <acceleration>-0.549438 0.088867 -5.20125 0 -0 0</acceleration>
          <wrench>-0.549438 0.088867 -5.20125 0 -0 0</wrench>
        </link>
        <link name='chassis'>
          <pose>-0.152301 -0.000193 0.499986 1.6e-05 1.4e-05 0.000267</pose>
          <velocity>-0.000833 1.7e-05 -0.001211 4e-06 -0.001702 -1.5e-05</velocity>
          <acceleration>-1.63822 0.040547 -2.42178 -3.13689 0.263742 3.10326</acceleration>
          <wrench>-1.87404 0.046384 -2.7704 0 -0 0</wrench>
        </link>
        <link name='left_wheel'>
          <pose>0.553239 0.625027 0.299985 -1.57069 -0.003393 0.000266</pose>
          <velocity>-0.000501 3e-06 0 -8e-06 -0.001672 -1.5e-05</velocity>
          <acceleration>-0.968572 0.005202 0.000773 3.12501 0.63017 3.10883</acceleration>
          <wrench>-1.93714 0.010404 0.001546 0 -0 0</wrench>
        </link>
        <link name='right_wheel'>
          <pose>0.553572 -0.625031 0.299966 -1.57068 -0.00229 0.000266</pose>
          <velocity>-0.000508 3e-06 -0 -9e-06 -0.001694 -2.5e-05</velocity>
          <acceleration>-0.993258 0.005621 0.000676 3.12312 0.724301 3.09089</acceleration>
          <wrench>-1.98652 0.011243 0.001352 0 -0 0</wrench>
        </link>
        <model name='ray_sensor_box'>
          <pose>0.822514 0 0.811819 0 -0 0</pose>
          <scale>1 1 1</scale>
          <link name='ray_link'>
            <pose>0.821644 6.2e-05 0.811791 1.5e-05 1.4e-05 0</pose>
            <velocity>-0.00136 2e-06 0.000443 6e-06 -0.001697 0</velocity>
            <acceleration>-2.69226 0.00168 0.886299 -3.12928 0.252587 3.14154</acceleration>
            <wrench>-2.69226 0.00168 0.886299 0 -0 0</wrench>
          </link>
        </model>
      </model>
      <light name='sun'>
        <pose>0 0 10 0 -0 0</pose>
      </light>
    </state>
    <gui fullscreen='0'>
      <camera name='user_camera'>
        <pose>23.2979 -15.3184 10.4726 0 0.435643 2.48419</pose>
        <view_controller>orbit</view_controller>
        <projection_type>perspective</projection_type>
      </camera>
    </gui>
  </world>
</sdf>
