<?xml version="1.0"?>
<!--
  Gazebo ROS differential drive plugin demo

  # MOVEMENT
  Try sending commands:

    ros2 topic pub /demo/cmd_demo geometry_msgs/Twist '{linear: {x: 1.0}}' -1

    ros2 topic pub /demo/cmd_demo geometry_msgs/Twist '{angular: {z: 0.1}}' -1

  Try listening to odometry:

    ros2 topic echo /demo/odom_demo

  Try listening to TF:

    ros2 run tf2_ros tf2_echo odom_demo chassis

    ros2 run tf2_ros tf2_echo chassis right_wheel

    ros2 run tf2_ros tf2_echo chassis left_wheel
    
    
  # SENSOR  
  Then open RVIZ:

      ros2 run rviz2 rviz2

  On RViz, add the following topics:

      * /ray/pointcloud2
      * /ray/pointcloud
      * /ray/laserscan
      * /gpu_ray/pointcloud2
      * /gpu_ray/pointcloud
      * /gpu_ray/laserscan    
    
-->
<sdf version="1.6">
  <world name="default">

    <include>
      <uri>model://ground_plane</uri>
    </include>

    <include>
      <uri>model://sun</uri>
    </include>


<!-- VEHICLE MODEL -->      
    <model name='vehicle'>
      <pose>0 0 0.325 0 -0 0</pose>

<!-- LINKS -->
      <link name='chassis'>
        <pose>-0.151427 -0 0.175 0 -0 0</pose>
        <inertial>
          <mass>1.14395</mass>
          <inertia>
            <ixx>0.126164</ixx>
            <ixy>0</ixy>
            <ixz>0</ixz>
            <iyy>0.416519</iyy>
            <iyz>0</iyz>
            <izz>0.481014</izz>
          </inertia>
        </inertial>
        <visual name='visual'>
          <geometry>
            <box>
              <size>2.01142 1 0.568726</size>
            </box>
          </geometry>
        </visual>
        <collision name='collision'>
          <geometry>
            <box>
              <size>2.01142 1 0.568726</size>
            </box>
          </geometry>
        </collision>
      </link>

      <link name='left_wheel'>
        <pose>0.554283 0.625029 -0.025 -1.5707 0 0</pose>
        <inertial>
          <mass>2</mass>
          <inertia>
            <ixx>0.145833</ixx>
            <ixy>0</ixy>
            <ixz>0</ixz>
            <iyy>0.145833</iyy>
            <iyz>0</iyz>
            <izz>0.125</izz>
          </inertia>
        </inertial>
        <visual name='visual'>
          <geometry>
            <sphere>
              <radius>0.3</radius>
            </sphere>
          </geometry>
        </visual>
        <collision name='collision'>
          <geometry>
            <sphere>
              <radius>0.3</radius>
            </sphere>
          </geometry>
          <surface>
            <friction>
              <ode>
                <mu>1</mu>
                <mu2>1</mu2>
                <slip1>0</slip1>
                <slip2>0</slip2>
              </ode>
            </friction>
            <contact>
              <ode>
                <soft_cfm>0</soft_cfm>
                <soft_erp>0.2</soft_erp>
                <kp>1e+13</kp>
                <kd>1</kd>
                <max_vel>0.01</max_vel>
                <min_depth>0.01</min_depth>
              </ode>
            </contact>
          </surface>
        </collision>
      </link>

      <link name='right_wheel'>
        <pose>0.554282 -0.625029 -0.025 -1.5707 0 0</pose>
        <inertial>
          <mass>2</mass>
          <inertia>
            <ixx>0.145833</ixx>
            <ixy>0</ixy>
            <ixz>0</ixz>
            <iyy>0.145833</iyy>
            <iyz>0</iyz>
            <izz>0.125</izz>
          </inertia>
        </inertial>
        <visual name='visual'>
          <geometry>
            <sphere>
              <radius>0.3</radius>
            </sphere>
          </geometry>
        </visual>
        <collision name='collision'>
          <geometry>
            <sphere>
              <radius>0.3</radius>
            </sphere>
          </geometry>
          <surface>
            <friction>
              <ode>
                <mu>1</mu>
                <mu2>1</mu2>
                <slip1>0</slip1>
                <slip2>0</slip2>
              </ode>
            </friction>
            <contact>
              <ode>
                <soft_cfm>0</soft_cfm>
                <soft_erp>0.2</soft_erp>
                <kp>1e+13</kp>
                <kd>1</kd>
                <max_vel>0.01</max_vel>
                <min_depth>0.01</min_depth>
              </ode>
            </contact>
          </surface>
        </collision>
      </link>

      <link name='caster'>
        <pose>-0.957138 -0 -0.125 0 -0 0</pose>
        <inertial>
          <mass>1</mass>
          <inertia>
            <ixx>0.1</ixx>
            <ixy>0</ixy>
            <ixz>0</ixz>
            <iyy>0.1</iyy>
            <iyz>0</iyz>
            <izz>0.1</izz>
          </inertia>
        </inertial>
        <visual name='visual'>
          <geometry>
            <sphere>
              <radius>0.2</radius>
            </sphere>
          </geometry>
        </visual>
        <collision name='collision'>
          <geometry>
            <sphere>
              <radius>0.2</radius>
            </sphere>
          </geometry>
        </collision>
      </link>
      
<!-- SENSOR MODEL -->      
      <model name="ray_sensor_box">
      <pose>0.822514 0 0.486819 0 -0 0</pose>
      <link name="ray_link">
        <visual name="visual_box">
          <geometry>
            <box>
              <size>0.05 0.05 0.05</size>
            </box>
          </geometry>
        </visual>
        <collision name="collision_box">
          <geometry>
            <box>
              <size>0.05 0.05 0.05</size>
            </box>
          </geometry>
          <laser_retro>100.0</laser_retro>
        </collision>

        <!-- ray sensor -->
        <sensor name="sensor_ray" type="ray">
          <ray>
            <scan>
              <horizontal>
                <samples>300</samples>
                <resolution>1.0</resolution>
                <min_angle>-0.5236</min_angle>
                <max_angle>0.5236</max_angle>
              </horizontal>
              <vertical>
                <samples>100</samples>
                <resolution>1.0</resolution>
                <min_angle>-0.5236</min_angle>
                <max_angle>0.5236</max_angle>
              </vertical>
            </scan>
            <range>
              <min>0.05</min>
              <max>50.0</max>
            </range>
          </ray>
          <always_on>true</always_on>
          <update_rate>1.0</update_rate>
          <plugin name="pc2" filename="libgazebo_ros_ray_sensor.so">
            <ros>
              <namespace>/ray</namespace>
              <remapping>~/out:=pointcloud2</remapping>
            </ros>
            <output_type>sensor_msgs/PointCloud2</output_type>
          </plugin>
          <plugin name="pc" filename="libgazebo_ros_ray_sensor.so">
            <ros>
              <namespace>/ray</namespace>
              <remapping>~/out:=pointcloud</remapping>
            </ros>
            <output_type>sensor_msgs/PointCloud</output_type>
          </plugin>
          <plugin name="laserscan" filename="libgazebo_ros_ray_sensor.so">
            <ros>
              <namespace>/ray</namespace>
              <remapping>~/out:=laserscan</remapping>
            </ros>
            <output_type>sensor_msgs/LaserScan</output_type>
          </plugin>
          <plugin name="range" filename="libgazebo_ros_ray_sensor.so">
            <ros>
              <namespace>/ray</namespace>
              <remapping>~/out:=range</remapping>
            </ros>
            <output_type>sensor_msgs/Range</output_type>
          </plugin>
        </sensor>

        <!-- gpu_ray sensor producing PointCloud / LaserScan -->
        <sensor name="sensor_gpu_ray" type="gpu_ray">
          <ray>
            <scan>
              <horizontal>
                <samples>300</samples>
                <resolution>1.0</resolution>
                <min_angle>-0.5236</min_angle>
                <max_angle>0.5236</max_angle>
              </horizontal>
              <!--
              gpu_ray currently only supports 1 vertical ray (no vertical tag)
              See https://bitbucket.org/osrf/gazebo/issues/2486
              <vertical>
                <samples>100</samples>
                <resolution>1.0</resolution>
                <min_angle>-0.5236</min_angle>
                <max_angle>0.5236</max_angle>
              </vertical-->
            </scan>
            <range>
              <min>0.05</min>
              <max>50.0</max>
            </range>
          </ray>
          <always_on>true</always_on>
          <update_rate>1.0</update_rate>
          <plugin name="pc2_gpu" filename="libgazebo_ros_ray_sensor.so">
            <ros>
              <namespace>/gpu_ray</namespace>
              <remapping>~/out:=pointcloud2</remapping>
            </ros>
            <output_type>sensor_msgs/PointCloud2</output_type>
          </plugin>
          <plugin name="pc_gpu" filename="libgazebo_ros_ray_sensor.so">
            <ros>
              <namespace>/gpu_ray</namespace>
              <remapping>~/out:=pointcloud</remapping>
            </ros>
            <output_type>sensor_msgs/PointCloud</output_type>
          </plugin>
          <plugin name="laserscan_gpu" filename="libgazebo_ros_ray_sensor.so">
            <ros>
              <namespace>/gpu_ray</namespace>
              <remapping>~/out:=laserscan</remapping>
            </ros>
            <output_type>sensor_msgs/LaserScan</output_type>
          </plugin>
          <plugin name="range_gpu" filename="libgazebo_ros_ray_sensor.so">
            <ros>
              <namespace>/gpu_ray</namespace>
              <remapping>~/out:=range</remapping>
            </ros>
            <output_type>sensor_msgs/Range</output_type>
          </plugin>
        </sensor>

      </link>
    </model>

<!-- JOINTS -->
      <joint name='left_wheel_joint' type='revolute'>
        <parent>chassis</parent>
        <child>left_wheel</child>
        <axis>
          <xyz>0 0 1</xyz>
          <limit>
            <lower>-1.79769e+308</lower>
            <upper>1.79769e+308</upper>
          </limit>
        </axis>
      </joint>

      <joint name='right_wheel_joint' type='revolute'>
        <parent>chassis</parent>
        <child>right_wheel</child>
        <axis>
          <xyz>0 0 1</xyz>
          <limit>
            <lower>-1.79769e+308</lower>
            <upper>1.79769e+308</upper>
          </limit>
        </axis>
      </joint>

      <joint name='caster_wheel' type='ball'>
        <parent>chassis</parent>
        <child>caster</child>
      </joint>

      <joint name="sensor_link" type="revolute">
       <parent>chassis</parent>
       <child>ray_link</child>
       <pose>0.0 0.0 0.0 0.0 0.0 0.0</pose>
       <axis>
        <xyz>0 0 1</xyz>
      </axis>
      </joint>

<!-- PLUGINS -->
      
      <plugin name='diff_drive' filename='libgazebo_ros_diff_drive.so'>

        <ros>
          <namespace>/demo</namespace>
          <remapping>cmd_vel:=cmd_demo</remapping>
          <remapping>odom:=odom_demo</remapping>
        </ros>

        <!-- wheels -->
        <left_joint>left_wheel_joint</left_joint>
        <right_joint>right_wheel_joint</right_joint>

        <!-- kinematics -->
        <wheel_separation>1.25</wheel_separation>
        <wheel_diameter>0.6</wheel_diameter>

        <!-- limits -->
        <max_wheel_torque>20</max_wheel_torque>
        <max_wheel_acceleration>1.0</max_wheel_acceleration>

        <!-- output -->
        <publish_odom>true</publish_odom>
        <publish_odom_tf>true</publish_odom_tf>
        <publish_wheel_tf>true</publish_wheel_tf>

        <odometry_frame>odom_demo</odometry_frame>
        <robot_base_frame>chassis</robot_base_frame>

      </plugin>

    </model>

  </world>
</sdf>
